Traceback (most recent call last):
  File "/Users/yewang/miniforge3/lib/python3.10/site-packages/jupyter_cache/executors/utils.py", line 58, in single_nb_execution
    executenb(
  File "/Users/yewang/miniforge3/lib/python3.10/site-packages/nbclient/client.py", line 1314, in execute
    return NotebookClient(nb=nb, resources=resources, km=km, **kwargs).execute()
  File "/Users/yewang/miniforge3/lib/python3.10/site-packages/jupyter_core/utils/__init__.py", line 165, in wrapped
    return loop.run_until_complete(inner)
  File "/Users/yewang/miniforge3/lib/python3.10/asyncio/base_events.py", line 649, in run_until_complete
    return future.result()
  File "/Users/yewang/miniforge3/lib/python3.10/site-packages/nbclient/client.py", line 709, in async_execute
    await self.async_execute_cell(
  File "/Users/yewang/miniforge3/lib/python3.10/site-packages/nbclient/client.py", line 1062, in async_execute_cell
    await self._check_raise_for_error(cell, cell_index, exec_reply)
  File "/Users/yewang/miniforge3/lib/python3.10/site-packages/nbclient/client.py", line 918, in _check_raise_for_error
    raise CellExecutionError.from_cell_and_msg(cell, exec_reply_content)
nbclient.exceptions.CellExecutionError: An error occurred while executing the following cell:
------------------
from pyswarm import pso

# ÂÆö‰πâÊçüÂ§±ÂáΩÊï∞
def loss_function(x):
    return np.sum(x**2)

# ÂÆö‰πâÊêúÁ¥¢Á©∫Èó¥
lb = [-5, -5]
ub = [5, 5]

# ÊâßË°åÁ≤íÂ≠êÁæ§‰ºòÂåñ
best_solution, best_loss = pso(loss_function, lb, ub, swarmsize=100, maxiter=100)

# ËæìÂá∫ÁªìÊûú
print(f'ÊúÄ‰ºòËß£: {best_solution}')
print(f'ÊúÄÂ∞èÊçüÂ§±: {best_loss}')
------------------


[0;31m---------------------------------------------------------------------------[0m
[0;31mModuleNotFoundError[0m                       Traceback (most recent call last)
Cell [0;32mIn[3], line 1[0m
[0;32m----> 1[0m [38;5;28;01mfrom[39;00m [38;5;21;01mpyswarm[39;00m [38;5;28;01mimport[39;00m pso
[1;32m      3[0m [38;5;66;03m# ÂÆö‰πâÊçüÂ§±ÂáΩÊï∞[39;00m
[1;32m      4[0m [38;5;28;01mdef[39;00m [38;5;21mloss_function[39m(x):

[0;31mModuleNotFoundError[0m: No module named 'pyswarm'

