Traceback (most recent call last):
  File "/Users/yewang/.local/pipx/venvs/jupyter-book/lib/python3.9/site-packages/jupyter_cache/executors/utils.py", line 58, in single_nb_execution
    executenb(
  File "/Users/yewang/.local/pipx/venvs/jupyter-book/lib/python3.9/site-packages/nbclient/client.py", line 1314, in execute
    return NotebookClient(nb=nb, resources=resources, km=km, **kwargs).execute()
  File "/Users/yewang/.local/pipx/venvs/jupyter-book/lib/python3.9/site-packages/jupyter_core/utils/__init__.py", line 165, in wrapped
    return loop.run_until_complete(inner)
  File "/Users/yewang/.pyenv/versions/3.9.15/lib/python3.9/asyncio/base_events.py", line 647, in run_until_complete
    return future.result()
  File "/Users/yewang/.local/pipx/venvs/jupyter-book/lib/python3.9/site-packages/nbclient/client.py", line 709, in async_execute
    await self.async_execute_cell(
  File "/Users/yewang/.local/pipx/venvs/jupyter-book/lib/python3.9/site-packages/nbclient/client.py", line 1062, in async_execute_cell
    await self._check_raise_for_error(cell, cell_index, exec_reply)
  File "/Users/yewang/.local/pipx/venvs/jupyter-book/lib/python3.9/site-packages/nbclient/client.py", line 918, in _check_raise_for_error
    raise CellExecutionError.from_cell_and_msg(cell, exec_reply_content)
nbclient.exceptions.CellExecutionError: An error occurred while executing the following cell:
------------------
import numpy as np
import matplotlib.pyplot as plt
from sklearn.datasets import load_iris
from sklearn.linear_model import LogisticRegression
import seaborn as sns

# 设置字体和解决负号显示问题
plt.rcParams['font.sans-serif'] = 'Hiragino Sans GB'
plt.rcParams['axes.unicode_minus'] = False

# 加载示例数据
iris = load_iris()
X, y = iris.data, iris.target

# 拟合逻辑回归模型
model = LogisticRegression(max_iter=200)
model.fit(X, y)

# 绘制分类结果
sns.scatterplot(x=X[:, 0], y=X[:, 1], hue=iris.target_names[y])
plt.title('逻辑回归分类示例')
plt.xlabel('特征 1')
plt.ylabel('特征 2')
plt.show()
------------------


[0;31m---------------------------------------------------------------------------[0m
[0;31mModuleNotFoundError[0m                       Traceback (most recent call last)
Cell [0;32mIn[1], line 1[0m
[0;32m----> 1[0m [38;5;28;01mimport[39;00m [38;5;21;01mnumpy[39;00m [38;5;28;01mas[39;00m [38;5;21;01mnp[39;00m
[1;32m      2[0m [38;5;28;01mimport[39;00m [38;5;21;01mmatplotlib[39;00m[38;5;21;01m.[39;00m[38;5;21;01mpyplot[39;00m [38;5;28;01mas[39;00m [38;5;21;01mplt[39;00m
[1;32m      3[0m [38;5;28;01mfrom[39;00m [38;5;21;01msklearn[39;00m[38;5;21;01m.[39;00m[38;5;21;01mdatasets[39;00m [38;5;28;01mimport[39;00m load_iris

[0;31mModuleNotFoundError[0m: No module named 'numpy'

